<?xml version="1.0" ?>
<mujoco model="base">
    <compiler angle="radian" meshdir="meshes/"/>
    <option timestep="0.001" impratio="20" density="1.2" viscosity="2e-05" cone="elliptic"/>
    <size njmax="5000" nconmax="5000"/>
    <visual>
        <map znear="0.001"/>
    </visual>
    <asset>
        <texture type="2d" name="texplane" builtin="checker" rgb1="0.2 0.3 0.4" rgb2="0.1 0.15 0.2" width="512" height="512"/>
        <texture type="2d" name="white_borders" file="/home/julius/robotics/robosuite/robosuite/models/assets/arenas/../textures/white_borders.png"/>
        <texture type="2d" name="white" file="/home/julius/robotics/robosuite/robosuite/models/assets/arenas/../textures/white-plaster.png"/>
        <texture type="2d" name="clay" file="/home/julius/robotics/robosuite/robosuite/models/assets/arenas/../textures/clay.png"/>
        <texture type="skybox" builtin="gradient" rgb1="0.9 0.9 1" rgb2="0.2 0.3 0.4" width="256" height="1536"/>
        <texture type="2d" name="tex-cream-plaster" file="/home/julius/robotics/robosuite/robosuite/models/assets/arenas/../textures/cream-plaster.png"/>
        <material name="MatGnd" texture="texplane" texuniform="true" reflectance="0.5"/>
        <material name="white_borders" texture="white_borders"/>
        <material name="white" texture="white"/>
        <material name="clay" texture="clay"/>
        <material name="floorplane" texture="texplane" texuniform="true" texrepeat="2 2" specular="0" shininess="0" reflectance="0.01"/>
        <material name="walls_mat" texture="tex-cream-plaster" texuniform="true" texrepeat="3 3" specular="0.1" shininess="0.1"/>
        <mesh name="table" file="/home/julius/robotics/robosuite/robosuite/models/assets/arenas/../meshes/table.stl"/>
        <mesh name="robot0_link0" file="/home/julius/robotics/robosuite/robosuite/models/assets/robots/panda/meshes/link0.stl"/>
        <mesh name="robot0_link1" file="/home/julius/robotics/robosuite/robosuite/models/assets/robots/panda/meshes/link1.stl"/>
        <mesh name="robot0_link2" file="/home/julius/robotics/robosuite/robosuite/models/assets/robots/panda/meshes/link2.stl"/>
        <mesh name="robot0_link3" file="/home/julius/robotics/robosuite/robosuite/models/assets/robots/panda/meshes/link3.stl"/>
        <mesh name="robot0_link4" file="/home/julius/robotics/robosuite/robosuite/models/assets/robots/panda/meshes/link4.stl"/>
        <mesh name="robot0_link5" file="/home/julius/robotics/robosuite/robosuite/models/assets/robots/panda/meshes/link5.stl"/>
        <mesh name="robot0_link6" file="/home/julius/robotics/robosuite/robosuite/models/assets/robots/panda/meshes/link6.stl"/>
        <mesh name="robot0_link7" file="/home/julius/robotics/robosuite/robosuite/models/assets/robots/panda/meshes/link7.stl"/>
        <mesh name="robot0_link0_vis" file="/home/julius/robotics/robosuite/robosuite/models/assets/robots/panda/meshes/link0_vis.stl"/>
        <mesh name="robot0_link1_vis" file="/home/julius/robotics/robosuite/robosuite/models/assets/robots/panda/meshes/link1_vis.stl"/>
        <mesh name="robot0_link2_vis" file="/home/julius/robotics/robosuite/robosuite/models/assets/robots/panda/meshes/link2_vis.stl"/>
        <mesh name="robot0_link3_vis" file="/home/julius/robotics/robosuite/robosuite/models/assets/robots/panda/meshes/link3_vis.stl"/>
        <mesh name="robot0_link4_vis" file="/home/julius/robotics/robosuite/robosuite/models/assets/robots/panda/meshes/link4_vis.stl"/>
        <mesh name="robot0_link5_vis" file="/home/julius/robotics/robosuite/robosuite/models/assets/robots/panda/meshes/link5_vis.stl"/>
        <mesh name="robot0_link6_vis" file="/home/julius/robotics/robosuite/robosuite/models/assets/robots/panda/meshes/link6_vis.stl"/>
        <mesh name="robot0_link7_vis" file="/home/julius/robotics/robosuite/robosuite/models/assets/robots/panda/meshes/link7_vis.stl"/>
        <mesh name="gripper0_finger_plastic" file="/home/julius/robotics/robosuite/robosuite/models/assets/grippers/meshes/panda_gripper/3dprinted_finger.stl"/>
        <mesh name="gripper0_hand" file="/home/julius/robotics/robosuite/robosuite/models/assets/grippers/meshes/panda_gripper/hand.stl"/>
        <mesh name="gripper0_hand_vis" file="/home/julius/robotics/robosuite/robosuite/models/assets/grippers/meshes/panda_gripper/hand_vis.stl"/>
        <mesh name="gripper0_finger" file="/home/julius/robotics/robosuite/robosuite/models/assets/grippers/meshes/panda_gripper/finger.stl"/>
        <mesh name="gripper0_finger_vis" file="/home/julius/robotics/robosuite/robosuite/models/assets/grippers/meshes/panda_gripper/finger_vis.stl"/>
        <mesh name="gripper0_finger_vis2" file="/home/julius/robotics/robosuite/robosuite/models/assets/grippers/meshes/panda_gripper/finger_longer.stl"/>
    </asset>
    <worldbody>
        <geom name="ground" size="5 5 10" type="plane" rgba="0.5 0.5 0 1"/>
        <camera name="frontview" pos="0.35 -0.1 0.25" quat="0.56 0.43 0.43 0.56"/>
        <camera name="clothview" pos="0.21 -0.12 0.35" quat="0.653 0.271 0.271 0.653"/>
        <camera name="clothview2" pos="0 -0.12 0.45" quat="0.7071 0 0 0.7071"/>
        <camera name="birdview" pos="-0.2 0 3" quat="0.7071 0 0 0.7071"/>
        <camera name="agentview" pos="0.5 0 1.35" quat="0.653 0.271 0.271 0.653"/>
        <camera name="sideview" pos="0.1 0.2 0.3" quat="0.2 0 0.5 0.75"/>
        <camera name="eye_in_hand" pos="0.05 0 0" quat="0 0.707108 0.707108 0" fovy="75"/>
        <camera name="robotview" pos="1 0 0.4" quat="0.653 0.271 0.271 0.653"/>
        <light name="foo" pos="1 1 4" dir="0 -0.14834 -0.988936" diffuse="0.8 0.8 0.8"/>
        <light name="bar" pos="-3 -3 4" dir="0 -0.14834 -0.988936" diffuse="0.8 0.8 0.8"/>
        <body name="tabletop" pos="0.3 0 0">
            <geom name="la_tabla_col" size="0.3 0.6 0.14" type="box" rgba="0.5 0.5 0 1"/>
            <geom name="la_tabla_vis" size="0.3 0.6 0.14" type="box" group="1" rgba="1 1 1 0.1"/>
        </body>
        <body name="robot0_base" pos="0 0 0">
            <camera name="robot0_robotview" pos="1 0 0.4" quat="0.653 0.271 0.271 0.653"/>
            <body name="robot0_link0" pos="0 0 0">
                <geom name="robot0_link0_visual" type="mesh" contype="0" conaffinity="0" group="1" rgba="1 1 1 1" mesh="robot0_link0_vis"/>
                <geom name="robot0_link0_collision" type="mesh" rgba="0 0.5 0 1" mesh="robot0_link0"/>
                <body name="robot0_link1" pos="0 0 0.333">
                    <joint name="robot0_joint1" pos="0 0 0" axis="0 0 1" limited="true" range="-2.8973 2.8973"  damping="0.0" frictionloss="0.0"/>
                    <geom name="robot0_link1_visual" type="mesh" contype="0" conaffinity="0" group="1" rgba="1 1 1 1" mesh="robot0_link1_vis"/>
                    <geom name="robot0_link1_collision" type="mesh" rgba="0 0.5 0 1" mesh="robot0_link1"/>
                    <body name="robot0_link2" pos="0 0 0" quat="0.707107 -0.707107 0 0">
                        <joint name="robot0_joint2" pos="0 0 0" axis="0 0 1" limited="true" range="-1.7628 1.7628"  damping="0.0" frictionloss="0.0"/>
                        <geom name="robot0_link2_visual" type="mesh" contype="0" conaffinity="0" group="1" rgba="1 1 1 1" mesh="robot0_link2_vis"/>
                        <geom name="robot0_link2_collision" type="mesh" rgba="0 0.5 0 1" mesh="robot0_link2"/>
                        <body name="robot0_link3" pos="0 -0.316 0" quat="0.707107 0.707107 0 0">
                            <joint name="robot0_joint3" pos="0 0 0" axis="0 0 1" limited="true" range="-2.8973 2.8973"  damping="0.0" frictionloss="0.0"/>
                            <geom name="robot0_link3_visual" type="mesh" contype="0" conaffinity="0" group="1" rgba="1 1 1 1" mesh="robot0_link3_vis"/>
                            <geom name="robot0_link3_collision" type="mesh" rgba="0 0.5 0 1" mesh="robot0_link3"/>
                            <body name="robot0_link4" pos="0.0825 0 0" quat="0.707107 0.707107 0 0">
                                <joint name="robot0_joint4" pos="0 0 0" axis="0 0 1" limited="true" range="-3.0718 -0.0698" damping="0.0" frictionloss="0.0"/>
                                <geom name="robot0_link4_visual" type="mesh" contype="0" conaffinity="0" group="1" rgba="1 1 1 1" mesh="robot0_link4_vis"/>
                                <geom name="robot0_link4_collision" type="mesh" rgba="0 0.5 0 1" mesh="robot0_link4"/>
                                <body name="robot0_link5" pos="-0.0825 0.384 0" quat="0.707107 -0.707107 0 0">
                                    <joint name="robot0_joint5" pos="0 0 0" axis="0 0 1" limited="true" range="-2.8973 2.8973"  damping="0.0" frictionloss="0.0"/>
                                    <geom name="robot0_link5_visual" type="mesh" contype="0" conaffinity="0" group="1" rgba="1 1 1 1" mesh="robot0_link5_vis"/>
                                    <geom name="robot0_link5_collision" type="mesh" rgba="0 0.5 0 1" mesh="robot0_link5"/>
                                    <body name="robot0_link6" pos="0 0 0" quat="0.707107 0.707107 0 0">
                                        <joint name="robot0_joint6" pos="0 0 0" axis="0 0 1" limited="true" range="-0.0175 3.7525"  damping="0.0" frictionloss="0.0"/>
                                        <geom name="robot0_link6_visual" type="mesh" contype="0" conaffinity="0" group="1" rgba="1 1 1 1" mesh="robot0_link6_vis"/>
                                        <geom name="robot0_link6_collision" type="mesh" rgba="0 0.5 0 1" mesh="robot0_link6"/>
                                        <body name="robot0_link7" pos="0.088 0 0" quat="0.707107 0.707107 0 0">
                                            <joint name="robot0_joint7" pos="0 0 0" axis="0 0 1" limited="true" range="-2.8973 2.8973"  damping="0.0" frictionloss="0.0"/>
                                            <geom name="robot0_link7_visual" type="mesh" contype="0" conaffinity="0" group="1" rgba="1 1 1 1" mesh="robot0_link7_vis"/>
                                            <geom name="robot0_link7_collision" type="mesh" rgba="0 0.5 0 1" mesh="robot0_link7"/>
                                            <body name="robot0_right_hand" pos="0 0 0.1065" quat="0.923785 0 0 -0.382911">
                                                <site name="robot0_ee" pos="0 0 0" size="0.01" group="1" rgba="0 0 1 1"/>
                                                <site name="robot0_ee_x" pos="0 0 0" quat="0.707105 0.707108 0 0" size="0.005 0.1" group="1" type="cylinder" rgba="1 0 0 0"/>
                                                <site name="robot0_ee_z" pos="0 0 0" quat="0.707105 0 0 0.707108" size="0.005 0.1" group="1" type="cylinder" rgba="0 0 1 0"/>
                                                <site name="robot0_ee_y" pos="0 0 0" quat="0.707105 0 0.707108 0" size="0.005 0.1" group="1" type="cylinder" rgba="0 1 0 0"/>
                                                <camera name="robot0_eye_in_hand" pos="0.05 0 0" quat="0 0.707108 0.707108 0" fovy="75"/>
                                                <body name="gripper0_right_gripper" pos="0 0 0" quat="0.707107 0 0 -0.707107">
                                                    <geom name="gripper0_hand_visual" quat="0.707107 0 0 0.707107" type="mesh" contype="0" conaffinity="0" group="1" rgba="1 1 1 1" mesh="gripper0_hand_vis"/>
                                                    <geom name="gripper0_hand_collision" quat="0.707107 0 0 0.707107" type="mesh" rgba="0 0 0.5 1" mesh="gripper0_hand"/>
                                                    <geom name="gripper0_grip_geom" size="0.0025" pos="0 0 0.16" group="1" rgba="1 0 0 0.5"/>
                                                    <site name="gripper0_ft_frame" pos="0 0 0" size="0.01" group="1" rgba="1 0 0 1"/>
                                                    <site name="gripper0_grip_site" pos="0 0 0.16" size="0.0025" group="1" rgba="1 0 0 0.5"/>
                                                    <body name="gripper0_leftfinger" pos="0 0 0.0524" quat="0.707107 0 0 0.707107">
                                                        <geom name="gripper0_finger1_visual" type="mesh" contype="0" conaffinity="0" group="1" rgba="0.499 0.499 0.499 1" mesh="gripper0_finger_plastic"/>
                                                        <geom name="gripper0_finger1_collision" type="mesh" contype="0" condim="4" rgba="0 0 0.5 1" mesh="gripper0_finger_plastic"/>
                                                        <body name="gripper0_finger_joint1_tip" pos="0 0.0085 0.056">
                                                            <geom name="gripper0_finger1_pad_collision" size="0.008 0.004 0.008" pos="0 -0.005 -0.015" quat="0 0 0 1" type="box" friction="2 0.05 0.0001" solref="0.01 0.5" rgba="0 0 0.5 1"/>
                                                        </body>
                                                    </body>
                                                    <body name="gripper0_rightfinger" pos="0 0 0.0524" quat="0.707107 0 0 0.707107">
                                                        <geom name="gripper0_finger2_visual" quat="0 0 0 1" type="mesh" contype="0" conaffinity="0" group="1" rgba="0.499 0.499 0.499 1" mesh="gripper0_finger_plastic"/>
                                                        <geom name="gripper0_finger2_collision" quat="0 0 0 1" type="mesh" contype="0" condim="4" rgba="0 0 0.5 1" mesh="gripper0_finger_plastic"/>
                                                        <body name="gripper0_finger_joint2_tip" pos="0 -0.0085 0.056">
                                                            <geom name="gripper0_finger2_pad_collision" size="0.008 0.004 0.008" pos="0 0.005 -0.015" quat="0 0 0 1" type="box" friction="2 0.05 0.0001" solref="0.01 0.5" rgba="0 0 0.5 1"/>
                                                        </body>
                                                    </body>
                                                </body>
                                            </body>
                                        </body>
                                    </body>
                                </body>
                            </body>
                        </body>
                    </body>
                </body>
            </body>
            <body name="mount0_base" pos="0 0 0">
            </body>
        </body>
    </worldbody>
    <actuator>
        <general name="robot0_torq_j1" joint="robot0_joint1" />
        <general name="robot0_torq_j2" joint="robot0_joint2" />
        <general name="robot0_torq_j3" joint="robot0_joint3" />
        <general name="robot0_torq_j4" joint="robot0_joint4" />
        <general name="robot0_torq_j5" joint="robot0_joint5" />
        <general name="robot0_torq_j6" joint="robot0_joint6" />
        <general name="robot0_torq_j7" joint="robot0_joint7" />
    </actuator>
    <sensor>
        <force site="gripper0_ft_frame" name="gripper0_force_ee"/>
        <torque site="gripper0_ft_frame" name="gripper0_torque_ee"/>
    </sensor>
    <keyframe>
        <key time="0.0" qpos="0.0 0.0 0.0 0.0 0.0 0.0 0.0"/>
    </keyframe>
</mujoco>